<mujoco model="dynamic_obstacles">
  <option timestep="0.002" gravity="0 0 -9.81"/>

  <asset>
    <texture name="grid" type="2d" builtin="checker" rgb1="0.8 0.8 0.8" rgb2="0.6 0.6 0.6" width="512" height="512"/>
    <material name="grid_mat" texture="grid" texrepeat="8 8" reflectance="0.1"/>
  </asset>

  <worldbody>
    <geom name="ground" type="plane" size="5 5 0.1" material="grid_mat"/>

    <!-- Walls -->
    <body name="walls" pos="0 0 0.25">
      <geom name="wall_north" type="box" pos="0 5 0" size="5 0.05 0.25" rgba="0.5 0.3 0.2 1"/>
      <geom name="wall_south" type="box" pos="0 -5 0" size="5 0.05 0.25" rgba="0.5 0.3 0.2 1"/>
      <geom name="wall_east" type="box" pos="5 0 0" size="0.05 5 0.25" rgba="0.5 0.3 0.2 1"/>
      <geom name="wall_west" type="box" pos="-5 0 0" size="0.05 5 0.25" rgba="0.5 0.3 0.2 1"/>
    </body>

    <!-- Dynamic obstacle 1: slides along y-axis -->
    <body name="dyn_obs_1" pos="2 0 0.15">
      <joint name="dyn_obs_1_slide" type="slide" axis="0 1 0" range="-2 2"/>
      <geom name="dyn_obs_1_geom" type="cylinder" size="0.2 0.15" rgba="0.9 0.3 0.1 1"/>
    </body>

    <!-- Dynamic obstacle 2: slides along x-axis -->
    <body name="dyn_obs_2" pos="0 2 0.15">
      <joint name="dyn_obs_2_slide" type="slide" axis="1 0 0" range="-2 2"/>
      <geom name="dyn_obs_2_geom" type="cylinder" size="0.15 0.15" rgba="0.9 0.5 0.1 1"/>
    </body>

    <!-- Static obstacle -->
    <body name="obstacle1" pos="3 1 0.15">
      <geom name="obs1" type="box" size="0.3 0.3 0.15" rgba="0.8 0.2 0.2 1"/>
    </body>

    <!-- Robot (identical to flat_ground.xml) -->
    <body name="robot_chassis" pos="0 0 0.1">
      <joint name="robot_free" type="free"/>
      <geom name="chassis" type="box" size="0.15 0.1 0.05" mass="2.0" rgba="0.2 0.4 0.8 1"/>
      <body name="left_wheel" pos="-0.15 0.12 -0.03">
        <joint name="left_wheel_joint" type="hinge" axis="0 1 0"/>
        <geom name="left_wheel_geom" type="cylinder" size="0.05 0.02" rgba="0.3 0.3 0.3 1" euler="90 0 0"/>
      </body>
      <body name="right_wheel" pos="-0.15 -0.12 -0.03">
        <joint name="right_wheel_joint" type="hinge" axis="0 1 0"/>
        <geom name="right_wheel_geom" type="cylinder" size="0.05 0.02" rgba="0.3 0.3 0.3 1" euler="90 0 0"/>
      </body>
      <body name="caster" pos="0.12 0 -0.04">
        <geom name="caster_geom" type="sphere" size="0.02" rgba="0.5 0.5 0.5 1"/>
      </body>
    </body>

    <body name="goal_marker" pos="4 4 0.05">
      <geom name="goal_geom" type="cylinder" size="0.1 0.05" rgba="0.2 0.8 0.2 0.5"/>
    </body>
  </worldbody>

  <actuator>
    <velocity name="left_motor" joint="left_wheel_joint" kv="1"/>
    <velocity name="right_motor" joint="right_wheel_joint" kv="1"/>
    <!-- Position actuators for dynamic obstacles (driven by simulation code) -->
    <position name="dyn_act_1" joint="dyn_obs_1_slide" kp="100"/>
    <position name="dyn_act_2" joint="dyn_obs_2_slide" kp="100"/>
  </actuator>
</mujoco>
